2025-03-25 12:45:24,604 INFO    MainThread:663421 [wandb_setup.py:_flush():67] Current SDK version is 0.19.8
2025-03-25 12:45:24,604 INFO    MainThread:663421 [wandb_setup.py:_flush():67] Configure stats pid to 663421
2025-03-25 12:45:24,604 INFO    MainThread:663421 [wandb_setup.py:_flush():67] Loading settings from /home/krkavinda/.config/wandb/settings
2025-03-25 12:45:24,604 INFO    MainThread:663421 [wandb_setup.py:_flush():67] Loading settings from /home/krkavinda/FusionLIVO/wandb/settings
2025-03-25 12:45:24,604 INFO    MainThread:663421 [wandb_setup.py:_flush():67] Loading settings from environment variables
2025-03-25 12:45:24,604 INFO    MainThread:663421 [wandb_init.py:setup_run_log_directory():647] Logging user logs to /home/krkavinda/FusionLIVO/wandb/run-20250325_124524-qbuv73l6/logs/debug.log
2025-03-25 12:45:24,604 INFO    MainThread:663421 [wandb_init.py:setup_run_log_directory():648] Logging internal logs to /home/krkavinda/FusionLIVO/wandb/run-20250325_124524-qbuv73l6/logs/debug-internal.log
2025-03-25 12:45:24,604 INFO    MainThread:663421 [wandb_init.py:init():761] calling init triggers
2025-03-25 12:45:24,604 INFO    MainThread:663421 [wandb_init.py:init():766] wandb.init called with sweep_config: {}
config: {'data_dir': '/home/krkavinda/Datasets/KITTI_raw/kitti_data/scan', 'calib_dir': '/home/krkavinda/Datasets/KITTI_raw/kitti_data/calib', 'pose_dir': '/home/krkavinda/Datasets/KITTI_raw/kitti_data/poses', 'sequences': {'train': ['00', '02', '08', '09'], 'val': ['03', '04', '05', '06', '07', '10'], 'test': ['01']}, 'modalities': {'left_rgb': 'image_02', 'right_rgb': 'image_03', 'depth': 'depth', 'velodyne': 'velodyne'}, 'seq_len': 50, 'img_height': 184, 'img_width': 608, 'hidden_size': 1000, 'cnn_backbone': 'resnet18', 'batch_size': 16, 'num_workers': 24, 'epochs': 5, 'learning_rate': 0.0001, 'weight_decay': 0.0001, 'log_project': 'FusionLIVO', 'model_save_path': 'stereo_deepvo.pth', 'pose_save_dir': 'pred_poses', 'plot_save_dir': 'plots', '_wandb': {}}
2025-03-25 12:45:24,604 INFO    MainThread:663421 [wandb_init.py:init():784] starting backend
2025-03-25 12:45:24,605 INFO    MainThread:663421 [wandb_init.py:init():788] sending inform_init request
2025-03-25 12:45:24,621 INFO    MainThread:663421 [backend.py:_multiprocessing_setup():101] multiprocessing start_methods=fork,spawn,forkserver, using: spawn
2025-03-25 12:45:24,621 INFO    MainThread:663421 [wandb_init.py:init():798] backend started and connected
2025-03-25 12:45:24,625 INFO    MainThread:663421 [wandb_init.py:init():891] updated telemetry
2025-03-25 12:45:24,638 INFO    MainThread:663421 [wandb_init.py:init():915] communicating run to backend with 90.0 second timeout
2025-03-25 12:45:25,076 INFO    MainThread:663421 [wandb_init.py:init():990] starting run threads in backend
2025-03-25 12:45:25,135 INFO    MainThread:663421 [wandb_run.py:_console_start():2375] atexit reg
2025-03-25 12:45:25,135 INFO    MainThread:663421 [wandb_run.py:_redirect():2227] redirect: wrap_raw
2025-03-25 12:45:25,135 INFO    MainThread:663421 [wandb_run.py:_redirect():2292] Wrapping output streams.
2025-03-25 12:45:25,135 INFO    MainThread:663421 [wandb_run.py:_redirect():2315] Redirects installed.
2025-03-25 12:45:25,136 INFO    MainThread:663421 [wandb_init.py:init():1032] run started, returning control to user process
2025-03-25 12:46:20,142 INFO    MsgRouterThr:663421 [mailbox.py:close():129] Closing mailbox, abandoning 1 handles.
2025-03-25 12:46:27,133 ERROR   MainThread:663421 [redirect.py:_on_write():661] error in stderr callback
Traceback (most recent call last):
  File "/home/krkavinda/Fusion-env/lib/python3.8/site-packages/wandb/sdk/lib/redirect.py", line 659, in _on_write
    cb(written_data)
  File "/home/krkavinda/Fusion-env/lib/python3.8/site-packages/wandb/sdk/wandb_run.py", line 2302, in <lambda>
    lambda data: self._console_raw_callback("stderr", data),
  File "/home/krkavinda/Fusion-env/lib/python3.8/site-packages/wandb/sdk/wandb_run.py", line 401, in wrapper_fn
    return func(self, *args, **kwargs)
  File "/home/krkavinda/Fusion-env/lib/python3.8/site-packages/wandb/sdk/wandb_run.py", line 1444, in _console_raw_callback
    self._backend.interface.publish_output_raw(name, data)
  File "/home/krkavinda/Fusion-env/lib/python3.8/site-packages/wandb/sdk/interface/interface.py", line 761, in publish_output_raw
    self._publish_output_raw(o)
  File "/home/krkavinda/Fusion-env/lib/python3.8/site-packages/wandb/sdk/interface/interface_shared.py", line 38, in _publish_output_raw
    self._publish(rec)
  File "/home/krkavinda/Fusion-env/lib/python3.8/site-packages/wandb/sdk/interface/interface_sock.py", line 39, in _publish
    self._sock_client.send_record_publish(record)
  File "/home/krkavinda/Fusion-env/lib/python3.8/site-packages/wandb/sdk/lib/sock_client.py", line 174, in send_record_publish
    self.send_server_request(server_req)
  File "/home/krkavinda/Fusion-env/lib/python3.8/site-packages/wandb/sdk/lib/sock_client.py", line 154, in send_server_request
    self._send_message(msg)
  File "/home/krkavinda/Fusion-env/lib/python3.8/site-packages/wandb/sdk/lib/sock_client.py", line 151, in _send_message
    self._sendall_with_error_handle(header + data)
  File "/home/krkavinda/Fusion-env/lib/python3.8/site-packages/wandb/sdk/lib/sock_client.py", line 130, in _sendall_with_error_handle
    sent = self._sock.send(data)
BrokenPipeError: [Errno 32] Broken pipe
2025-03-25 12:46:27,137 ERROR   MainThread:663421 [redirect.py:_on_write():661] error in stderr callback
Traceback (most recent call last):
  File "/home/krkavinda/Fusion-env/lib/python3.8/site-packages/wandb/sdk/lib/redirect.py", line 659, in _on_write
    cb(written_data)
  File "/home/krkavinda/Fusion-env/lib/python3.8/site-packages/wandb/sdk/wandb_run.py", line 2302, in <lambda>
    lambda data: self._console_raw_callback("stderr", data),
  File "/home/krkavinda/Fusion-env/lib/python3.8/site-packages/wandb/sdk/wandb_run.py", line 401, in wrapper_fn
    return func(self, *args, **kwargs)
  File "/home/krkavinda/Fusion-env/lib/python3.8/site-packages/wandb/sdk/wandb_run.py", line 1444, in _console_raw_callback
    self._backend.interface.publish_output_raw(name, data)
  File "/home/krkavinda/Fusion-env/lib/python3.8/site-packages/wandb/sdk/interface/interface.py", line 761, in publish_output_raw
    self._publish_output_raw(o)
  File "/home/krkavinda/Fusion-env/lib/python3.8/site-packages/wandb/sdk/interface/interface_shared.py", line 38, in _publish_output_raw
    self._publish(rec)
  File "/home/krkavinda/Fusion-env/lib/python3.8/site-packages/wandb/sdk/interface/interface_sock.py", line 39, in _publish
    self._sock_client.send_record_publish(record)
  File "/home/krkavinda/Fusion-env/lib/python3.8/site-packages/wandb/sdk/lib/sock_client.py", line 174, in send_record_publish
    self.send_server_request(server_req)
  File "/home/krkavinda/Fusion-env/lib/python3.8/site-packages/wandb/sdk/lib/sock_client.py", line 154, in send_server_request
    self._send_message(msg)
  File "/home/krkavinda/Fusion-env/lib/python3.8/site-packages/wandb/sdk/lib/sock_client.py", line 151, in _send_message
    self._sendall_with_error_handle(header + data)
  File "/home/krkavinda/Fusion-env/lib/python3.8/site-packages/wandb/sdk/lib/sock_client.py", line 130, in _sendall_with_error_handle
    sent = self._sock.send(data)
BrokenPipeError: [Errno 32] Broken pipe
2025-03-25 12:46:27,137 ERROR   MainThread:663421 [redirect.py:_on_write():661] error in stderr callback
Traceback (most recent call last):
  File "/home/krkavinda/Fusion-env/lib/python3.8/site-packages/wandb/sdk/lib/redirect.py", line 659, in _on_write
    cb(written_data)
  File "/home/krkavinda/Fusion-env/lib/python3.8/site-packages/wandb/sdk/wandb_run.py", line 2302, in <lambda>
    lambda data: self._console_raw_callback("stderr", data),
  File "/home/krkavinda/Fusion-env/lib/python3.8/site-packages/wandb/sdk/wandb_run.py", line 401, in wrapper_fn
    return func(self, *args, **kwargs)
  File "/home/krkavinda/Fusion-env/lib/python3.8/site-packages/wandb/sdk/wandb_run.py", line 1444, in _console_raw_callback
    self._backend.interface.publish_output_raw(name, data)
  File "/home/krkavinda/Fusion-env/lib/python3.8/site-packages/wandb/sdk/interface/interface.py", line 761, in publish_output_raw
    self._publish_output_raw(o)
  File "/home/krkavinda/Fusion-env/lib/python3.8/site-packages/wandb/sdk/interface/interface_shared.py", line 38, in _publish_output_raw
    self._publish(rec)
  File "/home/krkavinda/Fusion-env/lib/python3.8/site-packages/wandb/sdk/interface/interface_sock.py", line 39, in _publish
    self._sock_client.send_record_publish(record)
  File "/home/krkavinda/Fusion-env/lib/python3.8/site-packages/wandb/sdk/lib/sock_client.py", line 174, in send_record_publish
    self.send_server_request(server_req)
  File "/home/krkavinda/Fusion-env/lib/python3.8/site-packages/wandb/sdk/lib/sock_client.py", line 154, in send_server_request
    self._send_message(msg)
  File "/home/krkavinda/Fusion-env/lib/python3.8/site-packages/wandb/sdk/lib/sock_client.py", line 151, in _send_message
    self._sendall_with_error_handle(header + data)
  File "/home/krkavinda/Fusion-env/lib/python3.8/site-packages/wandb/sdk/lib/sock_client.py", line 130, in _sendall_with_error_handle
    sent = self._sock.send(data)
BrokenPipeError: [Errno 32] Broken pipe
2025-03-25 12:46:27,137 ERROR   MainThread:663421 [redirect.py:_on_write():661] error in stderr callback
Traceback (most recent call last):
  File "/home/krkavinda/Fusion-env/lib/python3.8/site-packages/wandb/sdk/lib/redirect.py", line 659, in _on_write
    cb(written_data)
  File "/home/krkavinda/Fusion-env/lib/python3.8/site-packages/wandb/sdk/wandb_run.py", line 2302, in <lambda>
    lambda data: self._console_raw_callback("stderr", data),
  File "/home/krkavinda/Fusion-env/lib/python3.8/site-packages/wandb/sdk/wandb_run.py", line 401, in wrapper_fn
    return func(self, *args, **kwargs)
  File "/home/krkavinda/Fusion-env/lib/python3.8/site-packages/wandb/sdk/wandb_run.py", line 1444, in _console_raw_callback
    self._backend.interface.publish_output_raw(name, data)
  File "/home/krkavinda/Fusion-env/lib/python3.8/site-packages/wandb/sdk/interface/interface.py", line 761, in publish_output_raw
    self._publish_output_raw(o)
  File "/home/krkavinda/Fusion-env/lib/python3.8/site-packages/wandb/sdk/interface/interface_shared.py", line 38, in _publish_output_raw
    self._publish(rec)
  File "/home/krkavinda/Fusion-env/lib/python3.8/site-packages/wandb/sdk/interface/interface_sock.py", line 39, in _publish
    self._sock_client.send_record_publish(record)
  File "/home/krkavinda/Fusion-env/lib/python3.8/site-packages/wandb/sdk/lib/sock_client.py", line 174, in send_record_publish
    self.send_server_request(server_req)
  File "/home/krkavinda/Fusion-env/lib/python3.8/site-packages/wandb/sdk/lib/sock_client.py", line 154, in send_server_request
    self._send_message(msg)
  File "/home/krkavinda/Fusion-env/lib/python3.8/site-packages/wandb/sdk/lib/sock_client.py", line 151, in _send_message
    self._sendall_with_error_handle(header + data)
  File "/home/krkavinda/Fusion-env/lib/python3.8/site-packages/wandb/sdk/lib/sock_client.py", line 130, in _sendall_with_error_handle
    sent = self._sock.send(data)
BrokenPipeError: [Errno 32] Broken pipe
2025-03-25 12:46:27,138 ERROR   MainThread:663421 [redirect.py:_on_write():661] error in stderr callback
Traceback (most recent call last):
  File "/home/krkavinda/Fusion-env/lib/python3.8/site-packages/wandb/sdk/lib/redirect.py", line 659, in _on_write
    cb(written_data)
  File "/home/krkavinda/Fusion-env/lib/python3.8/site-packages/wandb/sdk/wandb_run.py", line 2302, in <lambda>
    lambda data: self._console_raw_callback("stderr", data),
  File "/home/krkavinda/Fusion-env/lib/python3.8/site-packages/wandb/sdk/wandb_run.py", line 401, in wrapper_fn
    return func(self, *args, **kwargs)
  File "/home/krkavinda/Fusion-env/lib/python3.8/site-packages/wandb/sdk/wandb_run.py", line 1444, in _console_raw_callback
    self._backend.interface.publish_output_raw(name, data)
  File "/home/krkavinda/Fusion-env/lib/python3.8/site-packages/wandb/sdk/interface/interface.py", line 761, in publish_output_raw
    self._publish_output_raw(o)
  File "/home/krkavinda/Fusion-env/lib/python3.8/site-packages/wandb/sdk/interface/interface_shared.py", line 38, in _publish_output_raw
    self._publish(rec)
  File "/home/krkavinda/Fusion-env/lib/python3.8/site-packages/wandb/sdk/interface/interface_sock.py", line 39, in _publish
    self._sock_client.send_record_publish(record)
  File "/home/krkavinda/Fusion-env/lib/python3.8/site-packages/wandb/sdk/lib/sock_client.py", line 174, in send_record_publish
    self.send_server_request(server_req)
  File "/home/krkavinda/Fusion-env/lib/python3.8/site-packages/wandb/sdk/lib/sock_client.py", line 154, in send_server_request
    self._send_message(msg)
  File "/home/krkavinda/Fusion-env/lib/python3.8/site-packages/wandb/sdk/lib/sock_client.py", line 151, in _send_message
    self._sendall_with_error_handle(header + data)
  File "/home/krkavinda/Fusion-env/lib/python3.8/site-packages/wandb/sdk/lib/sock_client.py", line 130, in _sendall_with_error_handle
    sent = self._sock.send(data)
BrokenPipeError: [Errno 32] Broken pipe
2025-03-25 12:46:27,138 ERROR   MainThread:663421 [redirect.py:_on_write():661] error in stderr callback
Traceback (most recent call last):
  File "/home/krkavinda/Fusion-env/lib/python3.8/site-packages/wandb/sdk/lib/redirect.py", line 659, in _on_write
    cb(written_data)
  File "/home/krkavinda/Fusion-env/lib/python3.8/site-packages/wandb/sdk/wandb_run.py", line 2302, in <lambda>
    lambda data: self._console_raw_callback("stderr", data),
  File "/home/krkavinda/Fusion-env/lib/python3.8/site-packages/wandb/sdk/wandb_run.py", line 401, in wrapper_fn
    return func(self, *args, **kwargs)
  File "/home/krkavinda/Fusion-env/lib/python3.8/site-packages/wandb/sdk/wandb_run.py", line 1444, in _console_raw_callback
    self._backend.interface.publish_output_raw(name, data)
  File "/home/krkavinda/Fusion-env/lib/python3.8/site-packages/wandb/sdk/interface/interface.py", line 761, in publish_output_raw
    self._publish_output_raw(o)
  File "/home/krkavinda/Fusion-env/lib/python3.8/site-packages/wandb/sdk/interface/interface_shared.py", line 38, in _publish_output_raw
    self._publish(rec)
  File "/home/krkavinda/Fusion-env/lib/python3.8/site-packages/wandb/sdk/interface/interface_sock.py", line 39, in _publish
    self._sock_client.send_record_publish(record)
  File "/home/krkavinda/Fusion-env/lib/python3.8/site-packages/wandb/sdk/lib/sock_client.py", line 174, in send_record_publish
    self.send_server_request(server_req)
  File "/home/krkavinda/Fusion-env/lib/python3.8/site-packages/wandb/sdk/lib/sock_client.py", line 154, in send_server_request
    self._send_message(msg)
  File "/home/krkavinda/Fusion-env/lib/python3.8/site-packages/wandb/sdk/lib/sock_client.py", line 151, in _send_message
    self._sendall_with_error_handle(header + data)
  File "/home/krkavinda/Fusion-env/lib/python3.8/site-packages/wandb/sdk/lib/sock_client.py", line 130, in _sendall_with_error_handle
    sent = self._sock.send(data)
BrokenPipeError: [Errno 32] Broken pipe
2025-03-25 12:46:27,138 ERROR   MainThread:663421 [redirect.py:_on_write():661] error in stderr callback
Traceback (most recent call last):
  File "/home/krkavinda/Fusion-env/lib/python3.8/site-packages/wandb/sdk/lib/redirect.py", line 659, in _on_write
    cb(written_data)
  File "/home/krkavinda/Fusion-env/lib/python3.8/site-packages/wandb/sdk/wandb_run.py", line 2302, in <lambda>
    lambda data: self._console_raw_callback("stderr", data),
  File "/home/krkavinda/Fusion-env/lib/python3.8/site-packages/wandb/sdk/wandb_run.py", line 401, in wrapper_fn
    return func(self, *args, **kwargs)
  File "/home/krkavinda/Fusion-env/lib/python3.8/site-packages/wandb/sdk/wandb_run.py", line 1444, in _console_raw_callback
    self._backend.interface.publish_output_raw(name, data)
  File "/home/krkavinda/Fusion-env/lib/python3.8/site-packages/wandb/sdk/interface/interface.py", line 761, in publish_output_raw
    self._publish_output_raw(o)
  File "/home/krkavinda/Fusion-env/lib/python3.8/site-packages/wandb/sdk/interface/interface_shared.py", line 38, in _publish_output_raw
    self._publish(rec)
  File "/home/krkavinda/Fusion-env/lib/python3.8/site-packages/wandb/sdk/interface/interface_sock.py", line 39, in _publish
    self._sock_client.send_record_publish(record)
  File "/home/krkavinda/Fusion-env/lib/python3.8/site-packages/wandb/sdk/lib/sock_client.py", line 174, in send_record_publish
    self.send_server_request(server_req)
  File "/home/krkavinda/Fusion-env/lib/python3.8/site-packages/wandb/sdk/lib/sock_client.py", line 154, in send_server_request
    self._send_message(msg)
  File "/home/krkavinda/Fusion-env/lib/python3.8/site-packages/wandb/sdk/lib/sock_client.py", line 151, in _send_message
    self._sendall_with_error_handle(header + data)
  File "/home/krkavinda/Fusion-env/lib/python3.8/site-packages/wandb/sdk/lib/sock_client.py", line 130, in _sendall_with_error_handle
    sent = self._sock.send(data)
BrokenPipeError: [Errno 32] Broken pipe
2025-03-25 12:46:27,138 ERROR   MainThread:663421 [redirect.py:_on_write():661] error in stderr callback
Traceback (most recent call last):
  File "/home/krkavinda/Fusion-env/lib/python3.8/site-packages/wandb/sdk/lib/redirect.py", line 659, in _on_write
    cb(written_data)
  File "/home/krkavinda/Fusion-env/lib/python3.8/site-packages/wandb/sdk/wandb_run.py", line 2302, in <lambda>
    lambda data: self._console_raw_callback("stderr", data),
  File "/home/krkavinda/Fusion-env/lib/python3.8/site-packages/wandb/sdk/wandb_run.py", line 401, in wrapper_fn
    return func(self, *args, **kwargs)
  File "/home/krkavinda/Fusion-env/lib/python3.8/site-packages/wandb/sdk/wandb_run.py", line 1444, in _console_raw_callback
    self._backend.interface.publish_output_raw(name, data)
  File "/home/krkavinda/Fusion-env/lib/python3.8/site-packages/wandb/sdk/interface/interface.py", line 761, in publish_output_raw
    self._publish_output_raw(o)
  File "/home/krkavinda/Fusion-env/lib/python3.8/site-packages/wandb/sdk/interface/interface_shared.py", line 38, in _publish_output_raw
    self._publish(rec)
  File "/home/krkavinda/Fusion-env/lib/python3.8/site-packages/wandb/sdk/interface/interface_sock.py", line 39, in _publish
    self._sock_client.send_record_publish(record)
  File "/home/krkavinda/Fusion-env/lib/python3.8/site-packages/wandb/sdk/lib/sock_client.py", line 174, in send_record_publish
    self.send_server_request(server_req)
  File "/home/krkavinda/Fusion-env/lib/python3.8/site-packages/wandb/sdk/lib/sock_client.py", line 154, in send_server_request
    self._send_message(msg)
  File "/home/krkavinda/Fusion-env/lib/python3.8/site-packages/wandb/sdk/lib/sock_client.py", line 151, in _send_message
    self._sendall_with_error_handle(header + data)
  File "/home/krkavinda/Fusion-env/lib/python3.8/site-packages/wandb/sdk/lib/sock_client.py", line 130, in _sendall_with_error_handle
    sent = self._sock.send(data)
BrokenPipeError: [Errno 32] Broken pipe
